Workbook

Sheet لیست کارها
A1: فاز | B1: شناسه | C1: کار | D1: نوع | E1: اولویت | F1: وضعیت | G1: وابسته به | H1: مسئول | I1: تاریخ هدف | J1: توضیحات
A2: فاز ۰ — پایه و تصمیم‌ها | B2: P0-01 | C2: Commit و push تغییرات فعلی (پس از تأیید) و هم‌ترازکردن شاخه‌ها؛ ms سه commit جلوتر از origin/ms است | D2: عملیات | E2: بالا | F2: انجام شد | J2: کاربر commit و push را خودش انجام داد (آخرین: «portal toasts»). merge به master هنوز انجام نشده است (کار جدید P0-13).
A3: فاز ۰ — پایه و تصمیم‌ها | B3: P0-02 | C3: انتقال ClientKey، DNTCaptcha:EncryptionKey و ConnectionString از appsettings.json به User Secrets / secret store و چرخش کلیدها | D3: امنیت | E3: بالا | F3: به‌تعویق | J3: تصمیم کاربر: فعلاً مقدارها در appsettings.json باقی بمانند. قبل از استقرار نهایی/انتشار مخزن دوباره بررسی شود.
A4: فاز ۰ — پایه و تصمیم‌ها | B4: P0-03 | C4: اجرای migrationهای 003 و 004 روی دیتابیس واقعی و ثبت نتیجه verify | D4: عملیات | E4: بالا | F4: انجام شد | J4: حل شد: پشتیبان کامل masoud (oi_10202026_1217.bak) روی دیتابیس OrganizationIntranet برگردانده شد و 001 تا 004 را دارد؛ 005 هم با backup قبلی اعمال و verify شد. ۸ تست بانک واقعی قبول است. فایل‌های 003 هنوز در مخزن نیستند (کار P0-09).
A5: فاز ۰ — پایه و تصمیم‌ها | B5: P0-04 | C5: تصمیم و ثبت ADR: روش SSO (OIDC با IdP داخلی یا سرویس توکن ساده) | D5: تصمیم | E5: بالا | F5: به‌تعویق | J5: تصمیم کاربر: فعلاً مشخص نیست و بعداً انجام می‌شود.
A6: فاز ۰ — پایه و تصمیم‌ها | B6: P0-05 | C6: تصمیم و ثبت: منبع هویت کاربران (فعلاً جدول کاربران؛ AD/LDAP در آینده در صورت نیاز) | D6: تصمیم | E6: بالا | F6: انجام شد | J6: تصمیم فعلی: همین جدول کاربران (Sec.User). در صورت نیاز در آینده AD/LDAP بررسی می‌شود. این هنوز تصمیم نهایی معماری نیست.
A7: فاز ۰ — پایه و تصمیم‌ها | B7: P0-06 | C7: تصمیم: درگاه پیامک داخل شبکه است (بله) | D7: تصمیم | E7: متوسط | F7: انجام شد | J7: درگاه پیامک داخل شبکه است. کد آن در کار P6-08 اضافه شد (فعال‌سازی نیاز به AppName دارد).
A8: فاز ۰ — پایه و تصمیم‌ها | B8: P0-07 | C8: تعیین نقشه شبکه و استقرار: سرورها/دامنه‌های داخلی Portal، Admin و API؛ HTTPS با گواهی CA سازمان (تصمیم: HTTPS) | D8: عملیات | E8: متوسط | F8: در حال انجام | J8: تصمیم: HTTPS. هنوز مشخص نیست: نام سرورها و دامنه‌های داخلی و گواهی CA سازمان.
A9: فاز ۰ — پایه و تصمیم‌ها | B9: P0-08 | C9: ایجاد پروژه‌ی OrganizationIntranet.Tests و قاعده‌ی «هر تغییر یک تست» | D9: تست | E9: بالا | F9: انجام شد | J9: انجام شد: پروژه‌ی SmokeTests به OrganizationIntranet.Tests تبدیل شد (Unit/Integration/Database/Support + برچسب Category)، به solution اضافه شد، tests/README.md و قواعد ۱۵ و ۱۶ در CLAUDE.md نوشته شد. ۹۰ تست قبول، ۲ ردشده (بانک واقعی، اختیاری).
A10: فاز ۰ — پایه و تصمیم‌ها | B10: P0-09 | C10: تنظیم Api:ClientKey و Api:AdminClientKey در User Secrets هر سه برنامه | D10: عملیات | E10: بالا | F10: انجام شد | J10: انجام شد: کلیدهای تصادفی با dotnet user-secrets (PowerShell 7 برای tools/Initialize-Development.ps1 نصب نیست). برنامه‌های در حال اجرا باید دوباره راه‌اندازی شوند.
A11: فاز ۰ — پایه و تصمیم‌ها | B11: P0-10 | C11: افزودن فایل‌های 003_ApplicationCatalog (up/down/verify) به مخزن برای نصب‌های تازه | D11: دیتابیس | E11: متوسط | F11: انجام نشده | J11: دیتابیس فعلی آن را دارد ولی فایل‌هایش در مخزن نیست؛ masoud آن‌ها را نداشت. راه: ساخت از روی دیتابیس (Generate Scripts / تفاوت با 002) و بازبینی. 004 در tools/sql هست.
A12: فاز ۰ — پایه و تصمیم‌ها | B12: P0-11 | C12: اعمال migrationهای 006_NationalIdLogin و 007_PublicationImages روی بانک توسعه | D12: دیتابیس | E12: بالا | F12: انجام شد | J12: با backup COPY_ONLY+CHECKSUM (OrganizationIntranet_before_006_007_20261021_1516.bak)، verify هر دو موفق؛ ۹ تست بانک واقعی قبول. تاریخچه‌ی بانک: 001 تا 007.
A13: فاز ۰ — پایه و تصمیم‌ها | B13: P0-12 | C13: پاک‌سازی داده‌ی آزمایشی پیش از بهره‌برداری | D13: دیتابیس | E13: بالا | F13: انجام نشده | J13: برای تست اضافه شد: ۸ مطلب (+۱ پیش‌نویس)، سرویس اعلان روی سامانه‌های ۲ و ۵، اعلان‌ها و ۴ درخواست دسترسی. همه با عبارت «داده‌ی آزمایشی» در متن.
... A17: فاز ۱ — کار بدون اینترنت | B17: P1-03 | C17: اسکن همه فایل‌های cshtml/css/js برای هر اتصال بیرونی و رفع موارد باقی‌مانده | D17: توسعه | E17: متوسط | F17: انجام شد | J17: اسکن cshtml/css/js: اتصال بیرونی (CDN، Google Fonts) در صفحه‌ها و سبک‌های خود پروژه نیست.
A18: فاز ۱ — کار بدون اینترنت | B18: P1-04 | C18: تست همه صفحه‌ها با قطع اینترنت (حالت Offline) و ثبت نتیجه | D18: تست | E18: بالا | F18: انجام نشده
A19: فاز ۲ — پرتال عمومی | B19: P2-01 | C19: تعریف قرارداد «چه چیزی عمومی است» (سامانه IsPublic، اطلاعیه، فرم) | D19: تصمیم | E19: بالا | F19: انجام شد | J19: ملاک: سامانه‌ی فعال با IsPublic و مطلب منتشرشده با IsPublic جدید؛ docs/public-portal.md
A20: فاز ۲ — پرتال عمومی | B20: P2-02 | C20: ساخت endpointهای عمومی API با AllowAnonymous و Rate Limit (سامانه‌ها و اطلاعیه‌های عمومی) | D20: توسعه | E20: بالا | F20: انجام شد | G20: تعریف قرارداد عمومی | J20: PublicController (api/public/*) با AllowAnonymous، Rate Limit، DTO جدا و فقط‌خواندنی؛ کلید داخلی کلاینت همچنان لازم است
A21: فاز ۲ — پرتال عمومی | B21: P2-03 | C21: تغییر صفحه اول Portal: نمایش محتوای عمومی بدون لاگین + دکمه ورود؛ پس از لاگین نمایش کارت‌های اختصاصی، کارتابل و اعلان‌ها | D21: توسعه | E21: بالا | F21: انجام شد | G21: endpointهای عمومی | J21: / به /Portal می‌رود؛ ناشناس داده‌ی عمومی و دکمه‌ی ورود می‌بیند، بعد از ورود همان صفحه‌ی کامل. با مرورگر هم دیده شد
A22: فاز ۲ — پرتال عمومی | B22: P2-04 | C22: باز شدن صفحه جزئیات اطلاعیه‌های عمومی بدون لاگین | D22: توسعه | E22: متوسط | F22: انجام شد | G22: endpointهای عمومی | J22: /Publications و جزئیات برای ناشناس باز است؛ پیش‌نویس و غیرعمومی ۴۰۴ می‌دهد
A23: فاز ۲ — پرتال عمومی | B23: P2-05 | C23: آزمون امنیتی: کاربر ناشناس هیچ داده خصوصی (سامانه خصوصی، اعلان، کاربر) نبیند | D23: تست | E23: بالا | F23: انجام شد | J23: PublicPortalTests (۸ آزمون) + قید بانک؛ مسیرهای خصوصی API برای ناشناس ۴۰۱ است
A24: فاز ۲ — پرتال عمومی | B24: P2-06 | C24: اعمال migration 005_PublicPublications روی بانک و اجرای verify | D24: دیتابیس | E24: بالا | F24: انجام شد | G24: P0-03 (migration 003/004) | J24: انجام شد: با backup COPY_ONLY قبلی (OrganizationIntranet_before_005_*.bak در پوشه‌ی Backup سرور)، اعمال، verify، و اجرای دوباره (بی‌اثر). API واقعی روی SQL Server واقعی با درخواست ناشناس آزموده شد.
A25: فاز ۲ — پرتال عمومی | B25: P2-07 | C25: بازبینی داده: کدام سامانه‌ها در بانک «عمومی» هستند؟ | D25: امنیت | E25: بالا | F25: انجام نشده | J25: بانک masoud دو سامانه‌ی عمومی دارد: «مشاهده فیش حقوق» (RequiresLogin=false) و «درگاه واحد سازمان». سامانه‌ی فیش حقوق نباید برای ناشناس دیده شود مگر عمداً؛ قبل از رونمایی بازبینی شود.
A26: فاز ۲ — پرتال عمومی | B26: P2-08 | C26: اصلاح .gitignore تا فایل‌های database/migrations دیگر نادیده گرفته نشوند | D26: عملیات | E26: بالا | F26: انجام شد | J26: خط ۳۸۹ حذف شد؛ 005 در whitelist است. فایل‌های 003 باید از masoud گرفته و commit شوند.
A27: فاز ۳ — محتوای قابل مدیریت | B27: P3-01 | C27: طراحی جدول فرم‌ها و اسناد (عنوان، دسته، فایل/لینک، ترتیب، عمومی/خصوصی، فعال) + migration بالا/پایین/verify | D27: دیتابیس | E27: بالا | F27: انجام نشده | J27: Schema پیشنهادی: Notify یا App
A28: فاز ۳ — محتوای قابل مدیریت | B28: P3-02 | C28: طراحی جدول دسته‌بندی‌ها (قوانین و مقررات / فرم‌های سازمانی / انتشارات) + migration | D28: دیتابیس | E28: بالا | F28: انجام نشده | J28: جایگزین بلوک‌های ثابت # در Portal
A29: فاز ۳ — محتوای قابل مدیریت | B29: P3-03 | C29: طراحی جدول هشدار/Banner (متن، سطح، بازه نمایش، عمومی/خصوصی) + migration | D29: دیتابیس | E29: بالا | F29: انجام نشده | J29: مدل Publication فقط سه نوع دارد
A30: فاز ۳ — محتوای قابل مدیریت | B30: P3-04 | C30: تصمیم ذخیره فایل فرم‌ها (دیسک سرور یا دیتابیس)، محدودیت نوع و حجم، مسیر امن دانلود | D30: تصمیم | E30: بالا | F30: انجام نشده
A31: فاز ۳ — محتوای قابل مدیریت | B31: P3-05 | C31: Entity، Repository، Application Service، Controller و DTO برای فرم‌ها، دسته‌ها و هشدارها | D31: توسعه | E31: بالا | F31: انجام نشده | G31: طراحی جدول‌ها | J31: مطابق معماری لایه‌ای پنج‌پروژه‌ای
A32: فاز ۳ — محتوای قابل مدیریت | B32: P3-06 | C32: جایگزینی بلوک‌های ثابت قوانین/انتشارات/فرم‌ها در Portal با داده واقعی و حذف عددهای ثابت | D32: توسعه | E32: بالا | F32: انجام نشده | G32: API فرم‌ها و دسته‌ها
A33: فاز ۳ — محتوای قابل مدیریت | B33: P3-07 | C33: نمایش هشدارها در بالای Portal | D33: توسعه | E33: متوسط | F33: انجام نشده | G33: API هشدارها
A34: فاز ۳ — محتوای قابل مدیریت | B34: P3-08 | C34: تصویر شاخص اخبار و اسلایدر خودکار «اخبار سازمان» در صفحه‌ی اصلی (بالای سامانه‌ها) | D34: توسعه | E34: بالا | F34: انجام شد | J34: جدول Notify.PublicationImage (migration 007)، تشخیص نوع از امضای فایل، دید تصویر = دید مطلب، بارگذاری/حذف و پیش‌نمایش در پنل مدیریت؛ docs/portal-pages.md
A35: فاز ۳ — محتوای قابل مدیریت | B35: P3-09 | C35: پیوست فایل به مطالب (مثلاً PDF بخشنامه‌ها) با دانلود امن | D35: توسعه | E35: متوسط | F35: انجام نشده | G35: P3-04 | J35: هم‌راستا با تصمیم ذخیره‌ی فایل (P3-04)
A36: فاز ۴ — CRUD کامل در ادمین | B36: P4-01 | C36: Publications: حذف نرم/بایگانی، پین، زمان‌بندی انتشار، انتخاب عمومی/خصوصی | D36: توسعه | E36: بالا | F36: در حال انجام | J36: انجام شد: تصویر شاخص (migration 007)، عمومی/خصوصی، پیش‌نمایش کارت، صفحه‌بندی. باقی: حذف نرم/بایگانی، پین، زمان‌بندی انتشار.
A37: فاز ۴ — CRUD کامل در ادمین | B37: P4-02 | C37: صفحات Admin برای فرم‌ها/اسناد: لیست، ساخت، ویرایش، فعال/غیرفعال، حذف | D37: توسعه | E37: بالا | F37: انجام نشده | G37: فاز ۳
A38: فاز ۴ — CRUD کامل در ادمین | B38: P4-03 | C38: صفحات Admin برای دسته‌ها: CRUD کامل | D38: توسعه | E38: متوسط | F38: انجام نشده | G38: فاز ۳
A39: فاز ۴ — CRUD کامل در ادمین | B39: P4-04 | C39: صفحات Admin برای هشدارها: CRUD کامل | D39: توسعه | E39: متوسط | F39: انجام نشده | G39: فاز ۳
A40: فاز ۴ — CRUD کامل در ادمین | B40: P4-05 | C40: نقش‌ها: ویرایش نام/کد و جلوگیری از حذف نقش دارای کاربر یا Permission | D40: توسعه | E40: متوسط | F40: انجام شد | J40: صفحه‌ی Roles/Edit: ویرایش نام و کد (کد یکتا و با قالب معتبر؛ کد ADMIN و EXPERT ثابت)، اعضا و مجوزهای نقش، شمار کاربران/مجوزها در فهرست، حذف فقط برای نقش استفاده‌نشده. RoleManagementTests.
A41: فاز ۴ — CRUD کامل در ادمین | B41: P4-06 | C41: کاربران: بایگانی/حذف نرم، import گروهی (CSV یا AD) و ریست رمز توسط مدیر | D41: توسعه | E41: متوسط | F41: در حال انجام | G41: تصمیم منبع هویت | J41: انجام شد: تعیین رمز توسط مدیر در ویرایش کاربر، جستجوی پیشرفته و صفحه‌بندی، ورود با کد ملی. باقی: بایگانی/حذف نرم، import گروهی.
A42: فاز ۴ — CRUD کامل در ادمین | B42: P4-07 | C42: محتوای ثابت Portal (تماس با فناوری اطلاعات، فوتر، متن‌ها) از تنظیمات/دیتابیس و قابل ویرایش در Admin | D42: توسعه | E42: پایین | F42: انجام نشده
A43: فاز ۴ — CRUD کامل در ادمین | B43: P4-08 | C43: Audit کامل: ثبت چه کسی چه چیزی را تغییر داد برای همه عملیات ادمین | D43: امنیت | E43: متوسط | F43: انجام نشده | J43: الان فقط لاگ ساده دارد
...

Sheet خلاصه پیشرفت
A1: فاز | B1: کل کارها | C1: انجام شد | D1: در حال انجام | E1: مسدود | F1: به‌تعویق | G1: انجام نشده | H1: درصد پیشرفت
A2: فاز ۰ — پایه و تصمیم‌ها | B2: =COUNTIF('لیست کارها'!$A$2:$A$78,A2) -> 13 | C2: =COUNTIFS('لیست کارها'!$A$2:$A$78,A2,'لیست کارها'!$F$2:$F$78,"انجام شد") -> 7 | D2: =COUNTIFS('لیست کارها'!$A$2:$A$78,A2,'لیست کارها'!$F$2:$F$78,"در حال انجام") -> 1 | E2: =COUNTIFS('لیست کارها'!$A$2:$A$78,A2,'لیست کارها'!$F$2:$F$78,"مسدود") -> 0 | F2: =COUNTIFS('لیست کارها'!$A$2:$A$78,A2,'لیست کارها'!$F$2:$F$78,"به‌تعویق") -> 2 | G2: =COUNTIFS('لیست کارها'!$A$2:$A$78,A2,'لیست کارها'!$F$2:$F$78,"انجام نشده") -> 3 | H2: =IFERROR(C2/B2,0) -> 0.53846154
A3: فاز ۱ — کار بدون اینترنت | B3: =COUNTIF('لیست کارها'!$A$2:$A$78,A3) -> 4 | C3: =COUNTIFS('لیست کارها'!$A$2:$A$78,A3,'لیست کارها'!$F$2:$F$78,"انجام شد") -> 3 | D3: =COUNTIFS('لیست کارها'!$A$2:$A$78,A3,'لیست کارها'!$F$2:$F$78,"در حال انجام") -> 0 | E3: =COUNTIFS('لیست کارها'!$A$2:$A$78,A3,'لیست کارها'!$F$2:$F$78,"مسدود") -> 0 | F3: =COUNTIFS('لیست کارها'!$A$2:$A$78,A3,'لیست کارها'!$F$2:$F$78,"به‌تعویق") -> 0 | G3: =COUNTIFS('لیست کارها'!$A$2:$A$78,A3,'لیست کارها'!$F$2:$F$78,"انجام نشده") -> 1 | H3: =IFERROR(C3/B3,0) -> 0.75
A4: فاز ۲ — پرتال عمومی | B4: =COUNTIF('لیست کارها'!$A$2:$A$78,A4) -> 8 | C4: =COUNTIFS('لیست کارها'!$A$2:$A$78,A4,'لیست کارها'!$F$2:$F$78,"انجام شد") -> 7 | D4: =COUNTIFS('لیست کارها'!$A$2:$A$78,A4,'لیست کارها'!$F$2:$F$78,"در حال انجام") -> 0 | E4: =COUNTIFS('لیست کارها'!$A$2:$A$78,A4,'لیست کارها'!$F$2:$F$78,"مسدود") -> 0 | F4: =COUNTIFS('لیست کارها'!$A$2:$A$78,A4,'لیست کارها'!$F$2:$F$78,"به‌تعویق") -> 0 | G4: =COUNTIFS('لیست کارها'!$A$2:$A$78,A4,'لیست کارها'!$F$2:$F$78,"انجام نشده") -> 1 | H4: =IFERROR(C4/B4,0) -> 0.875
A5: فاز ۳ — محتوای قابل مدیریت | B5: =COUNTIF('لیست کارها'!$A$2:$A$78,A5) -> 9 | C5: =COUNTIFS('لیست کارها'!$A$2:$A$78,A5,'لیست کارها'!$F$2:$F$78,"انجام شد") -> 1 | D5: =COUNTIFS('لیست کارها'!$A$2:$A$78,A5,'لیست کارها'!$F$2:$F$78,"در حال انجام") -> 0 | E5: =COUNTIFS('لیست کارها'!$A$2:$A$78,A5,'لیست کارها'!$F$2:$F$78,"مسدود") -> 0 | F5: =COUNTIFS('لیست کارها'!$A$2:$A$78,A5,'لیست کارها'!$F$2:$F$78,"به‌تعویق") -> 0 | G5: =COUNTIFS('لیست کارها'!$A$2:$A$78,A5,'لیست کارها'!$F$2:$F$78,"انجام نشده") -> 8 | H5: =IFERROR(C5/B5,0) -> 0.11111111
A6: فاز ۴ — CRUD کامل در ادمین | B6: =COUNTIF('لیست کارها'!$A$2:$A$78,A6) -> 11 | C6: =COUNTIFS('لیست کارها'!$A$2:$A$78,A6,'لیست کارها'!$F$2:$F$78,"انجام شد") -> 3 | D6: =COUNTIFS('لیست کارها'!$A$2:$A$78,A6,'لیست کارها'!$F$2:$F$78,"در حال انجام") -> 2 | E6: =COUNTIFS('لیست کارها'!$A$2:$A$78,A6,'لیست کارها'!$F$2:$F$78,"مسدود") -> 0 | F6: =COUNTIFS('لیست کارها'!$A$2:$A$78,A6,'لیست کارها'!$F$2:$F$78,"به‌تعویق") -> 0 | G6: =COUNTIFS('لیست کارها'!$A$2:$A$78,A6,'لیست کارها'!$F$2:$F$78,"انجام نشده") -> 6 | H6: =IFERROR(C6/B6,0) -> 0.27272727
A7: فاز ۵ — SSO | B7: =COUNTIF('لیست کارها'!$A$2:$A$78,A7) -> 6 | C7: =COUNTIFS('لیست کارها'!$A$2:$A$78,A7,'لیست کارها'!$F$2:$F$78,"انجام شد") -> 0 | D7: =COUNTIFS('لیست کارها'!$A$2:$A$78,A7,'لیست کارها'!$F$2:$F$78,"در حال انجام") -> 1 | E7: =COUNTIFS('لیست کارها'!$A$2:$A$78,A7,'لیست کارها'!$F$2:$F$78,"مسدود") -> 0 | F7: =COUNTIFS('لیست کارها'!$A$2:$A$78,A7,'لیست کارها'!$F$2:$F$78,"به‌تعویق") -> 0 | G7: =COUNTIFS('لیست کارها'!$A$2:$A$78,A7,'لیست کارها'!$F$2:$F$78,"انجام نشده") -> 5 | H7: =IFERROR(C7/B7,0) -> 0
A8: فاز ۶ — امنیت و بهره‌برداری | B8: =COUNTIF('لیست کارها'!$A$2:$A$78,A8) -> 14 | C8: =COUNTIFS('لیست کارها'!$A$2:$A$78,A8,'لیست کارها'!$F$2:$F$78,"انجام شد") -> 5 | D8: =COUNTIFS('لیست کارها'!$A$2:$A$78,A8,'لیست کارها'!$F$2:$F$78,"در حال انجام") -> 3 | E8: =COUNTIFS('لیست کارها'!$A$2:$A$78,A8,'لیست کارها'!$F$2:$F$78,"مسدود") -> 0 | F8: =COUNTIFS('لیست کارها'!$A$2:$A$78,A8,'لیست کارها'!$F$2:$F$78,"به‌تعویق") -> 2 | G8: =COUNTIFS('لیست کارها'!$A$2:$A$78,A8,'لیست کارها'!$F$2:$F$78,"انجام نشده") -> 4 | H8: =IFERROR(C8/B8,0) -> 0.35714286
A9: فاز ۷ — تجربه‌ی کاربری (UI/UX) | B9: =COUNTIF('لیست کارها'!$A$2:$A$78,A9) -> 12 | C9: =COUNTIFS('لیست کارها'!$A$2:$A$78,A9,'لیست کارها'!$F$2:$F$78,"انجام شد") -> 10 | D9: =COUNTIFS('لیست کارها'!$A$2:$A$78,A9,'لیست کارها'!$F$2:$F$78,"در حال انجام") -> 0 | E9: =COUNTIFS('لیست کارها'!$A$2:$A$78,A9,'لیست کارها'!$F$2:$F$78,"مسدود") -> 0 | F9: =COUNTIFS('لیست کارها'!$A$2:$A$78,A9,'لیست کارها'!$F$2:$F$78,"به‌تعویق") -> 0 | G9: =COUNTIFS('لیست کارها'!$A$2:$A$78,A9,'لیست کارها'!$F$2:$F$78,"انجام نشده") -> 2 | H9: =IFERROR(C9/B9,0) -> 0.83333333
A10: جمع کل | B10: =SUM(B2:B9) -> 77 | C10: =SUM(C2:C9) -> 36 | D10: =SUM(D2:D9) -> 7 | E10: =SUM(E2:E9) -> 0 | F10: =SUM(F2:F9) -> 4 | G10: =SUM(G2:G9) -> 30 | H10: =IFERROR(C10/B10,0) -> 0.46753247
A12: اعداد این برگه از «لیست کارها» محاسبه می‌شوند و نباید دستی تغییر کنند.

Sheet وضعیت فعلی
A1: قابلیت | B1: وضعیت | C1: شاهد
A2: پرتال عمومی بدون لاگین | B2: دارد | C2: سامانه‌ها و مطالب عمومی؛ ناشناس هیچ داده‌ی خصوصی نمی‌بیند (PublicPortalTests)
A3: سامانه‌ها، اعلان، درخواست دسترسی و اطلاعیه در Portal | B3: دارد | C3: صفحه‌های اعلان‌ها (تب‌دار) و درخواست دسترسی جدا ساخته شد
A4: اخبار تصویری و اسلایدر | B4: دارد | C4: تصویر شاخص با مدیریت در پنل؛ migration 007
A5: فرم‌ها و قوانین و مقررات | B5: ندارد | C5: هنوز لینک‌های ثابت # در صفحه‌ی اصلی؛ جدول و صفحه‌ی مدیریت ندارد (فاز ۳)
A6: هشدار / Banner | B6: ندارد | C6: فاز ۳
A7: SSO | B7: ندارد | C7: تصمیم روش به تعویق افتاده (P0-04)
A8: کار بدون اینترنت | B8: دارد | C8: فونت و همه‌ی دارایی‌ها محلی‌اند؛ آزمون واقعی بدون اینترنت (P1-04) باقی است
A9: ورود: رمز، LDAP، کد ملی و پیامک، دومرحله‌ای | B9: دارد | C9: Google Authenticator و پیامک؛ ارسال واقعی پیامک آزموده نشده
A10: Admin: کاربران | B10: دارد | C10: لیست با صفحه‌بندی و جستجوی پیشرفته، ویرایش، فعال/غیرفعال؛ بایگانی و import ندارد
A11: Admin: Publications | B11: نسبی | C11: ساخت، ویرایش، تصویر، عمومی/خصوصی؛ حذف/بایگانی، پین و زمان‌بندی ندارد
A12: Admin: نقش‌ها | B12: دارد | C12: ساخت، ویرایش نام/کد، جزئیات اعضا و مجوزها، شمارها، فعال/غیرفعال، حذف نقش استفاده‌نشده
... A16: داده‌ی آزمایشی در بانک توسعه | B16: دارد | C16: باید پیش از بهره‌برداری پاک شود

Sheet تصمیمات لازم
A1: سؤال | B1: اثر تصمیم | C1: پاسخ
A2: کاربران از Active Directory سازمان وارد می‌شوند یا همین جدول کاربران؟ | B2: ورود، SSO، ایمپورت کاربران | C2: فعلاً همین جدول کاربران (Sec.User). در آینده در صورت نیاز تغییر می‌کند؛ تصمیم نهایی معماری نیست.
A3: سامانه‌هایی که باید SSO شوند چند تا هستند و با چه فناوری‌هایی نوشته شده‌اند؟ | B3: انتخاب پروتکل SSO | C3: فعلاً مشخص نیست؛ بعداً انجام می‌شود.
A4: درگاه پیامک داخل شبکه سازمان است؟ | B4: ورود با پیامک و اعلان درخواست دسترسی | C4: بله، داخل شبکه است؛ کد آن اضافه شد.
A5: پروتکل شبکه برای Portal، Admin و API؟ | B5: استقرار و گواهی | C5: HTTPS. نام سرورها/دامنه‌ها و گواهی CA سازمان هنوز مشخص نیست.
A6: کدام سامانه‌ها واقعاً «عمومی» باشند (مثلاً فیش حقوق)؟ | B6: دید بازدیدکننده‌ی ناشناس | C6: بعداً در یک فهرست کلی مشخص می‌شود؛ فعلاً به همین صورت آزمایشی بماند.
A7: فایل فرم‌ها و پیوست مطالب کجا ذخیره شود (دیسک سرور یا بانک) و سقف حجم؟ | B7: فاز ۳ | C7: روی دیسک، در پوشه‌ی Downloads درایو C؛ مسیر در تنظیمات قابل تغییر باشد (برای استقرار روی سرور بازبینی شود).
A8: ورود با کد ملی و پیامک یک‌عاملی است؛ برای چه کاربرانی فعال شود؟ | B8: امنیت ورود | C8: به تعویق افتاد؛ هنوز بحث نشده و شاید همان ورود با نام کاربری و رمز کافی باشد.
A9: مطالب قدیمی حذف شوند یا بایگانی؟ مدت نگه‌داری؟ | B9: P4-01 | C9: نیاز به بحث دارد؛ فعلاً سراغ آن نمی‌رویم.
